Workbook

Sheet 2013-14
C1: octobre | D1: novembre | E1: décembre | F1: janvier | G1: février | H1: mars | I1: avril | J1: mai | K1: juin | L1: juillet | M1: août | N1: septembre
A2: toutain | B2: 47000 | D2: 25000 | E2: 22000
D3: 31686 | E3: 15141
A4: maurice | B4: 31462 | D4: 20000 | F4: 20700
D5: 10751 | F5: 24190
A6: landron | B6: 21110 | D6: 12000 | E6: 9110 | F6: 4000 | G6: 4000
D7: 6428 | E7: 10450 | G7: 4217
A8: leloup | B8: 34990 | D8: 15000 | F8: 19990
D9: 12264 | F9: 22276
A10: mary etienne | B10: 7013 | E10: 7013
E11: 7013
A12: lefebvre letourneur | B12: 2277 | D12: 2277
D13: 2277
A14: delacotte | B14: 4736 | E14: 1551 | G14: 3407
E15: 1551 | G15: 3407
A16: fablet | B16: 1209 | D16: 1209
D17: 1209
A18: foulquier leveziel | B18: 9448 | D18: 9448
D19: 9448
A20: marie toit mondeville | B20: 12155 | H20: 12155
H21: 16461
A22: dechauffour | B22: 60000 | F22: 20000 | G22: 20000 | I22: 20000
F23: 15114 | G23: 20145 | I23: 17593
A24: moulinet | B24: 42000 | G24: 20000 | I24: 11000 | K24: 12627
G25: 18475 | I25: 18026 | K25: 12172
A26: lycée malherbe | B26: 1500 | D26: 1500
D27: 1500
A28: feve damien | B28: 7000 | D28: 3000 | E28: 4000
D29: 4325 | E29: 2604
A30: mme etienne martine | B30: 7958 | D30: 4500 | E30: 3500
D31: 4772 | E31: 3186
A32: urban | B32: 55060 | E32: 15000 | I32: 17000 | J32: 10000 | L32: 10000
E33: 18362 | I33: 14190 | J33: 12702 | L33: 11624
A34: rf girard-marais | B34: 4911 | D34: 4911
D35: 4911
A36: pasquet menuiseries | B36: 2995 | D36: 2995 | I36: 314 | J36: 1214
D37: 2995 | I37: 314 | J37: 1214
A38: dauvergne | B38: 15084 | E38: 4000 | G38: 4752 | H38: 6300
E39: 5295 | G39: 4752 | H39: 8430
A40: carre | B40: 797 | G40: 797
...

Sheet 2014-15
A1: Noms | B1: CA prévu | C1: octobre | D1: novembre | E1: décembre | F1: janvier | G1: février | H1: mars | I1: avril | J1: mai | K1: juin | L1: juillet | M1: août | N1: septembre
A2: guilbert thales | B2: 20031 | D2: 17446 | E2: 2585
D3: 17446 | E3: 2776
A4: chaventre | D4: 19000
D5: 25862
A6: bisson | D6: 16000 | G6: 15000
D7: 13076 | G7: 14668
A8: mazonni | B8: 11095 | D8: 3680 | F8: 7415 | H8: 2321
D9: 3680 | F9: 7415 | H9: 2321
A10: chaignet -dubois | B10: 65149 | C10: 11357 | D10: 11241 | E10: 21387 | F10: 5195 | G10: 10000 | H10: 5969
C11: 11357 | D11: 11241 | E11: 21387 | F11: 5195 | G11: 7088 | H11: 3880
A12: saillard | B12: 56109 | C12: 10476 | F12: 15428 | G12: 5312 | H12: 14720 | I12: 7230 | K12: 1122
C13: 10476 | F13: 15428 | G13: 5312 | H13: 14720 | I13: 7230 | K13: 1122
A14: dumont cocain | B14: 3838
A16: dumont lelong | B16: 11645 | E16: 5000 | F16: 6645
C17: 2387 | E17: 3464 | F17: 5794
A18: freire olivier | B18: 36354 | E18: 8507 | F18: 9682 | I18: 18000 | N18: 285
E19: 8507 | F19: 9682 | I19: 17389 | J19: 2310 | N19: 285
A20: freire bozec | B20: 27221 | C20: 6306 | D20: 2090 | G20: 9541 | H20: 9284
C21: 6306 | D21: 2090 | G21: 9541 | H21: 9284
A22: lemauf | B22: 2674 | D22: 2674
D23: 2674
A24: lemasle reno | B24: 33800 | D24: 10796 | G24: 21595
D25: 10796 | G25: 21595
A26: jeanne françoise | B26: 2000
A28: isoplaf devaux charp | B28: 11186 | C28: 3806 | E28: 7380
C29: 3806 | E29: 7379
A30: breteau mob | B30: 52000 | I30: 10750 | K30: 22144 | L30: 6926 | N30: 12180
I31: 10750 | K31: 22144 | L31: 6926 | N31: 13167
A32: scournec jean max | B32: 4806 | H32: 521 | J32: 4285
H33: 521 | J33: 4400
A34: rocton mob | B34: 16335 | C34: 7130 | E34: 4873 | G34: 4332
C35: 7130 | E35: 4873 | G35: 5071
A36: michel vinc mob | B36: 17702 | C36: 5000 | D36: 5000 | F36: 7702
C37: 4964 | D37: 4860 | F37: 11703
A38: perin | B38: 6800 | C38: 6800
C39: 3206
A40: viquesnel | B40: 23500 | C40: 23500
C41: 16329
A42: freire daniel | B42: 4000 | D42: 4000
...

Sheet 2015-16
C1: OCTOBRE | E1: NOVEMBRE | G1: DECEMBRE | I1: JANVIER | K1: FEVRIER | M1: MARS | O1: AVRIL | Q1: MAI | S1: JUIN | U1: JUILLET | W1: AOUT | Y1: SEPTEMBRE
A2: NOM | B2: CA/contrat | C2: prévu | D2: réalisé | E2: prévu | F2: réalisé | G2: prévu | H2: réalisé | I2: prévu | J2: réalisé | K2: prévu | L2: réalisé | M2: prévu | N2: réalisé | O2: prévu | P2: réalisé | Q2: prévu | R2: réalisé | S2: prévu | T2: réalisé | U2: prévu | V2: réalisé | W2: prévu | X2: réalisé | Y2: prévu | Z2: réalisé
A3: PASQUET commission | B3: 5199 | C3: 1848 | D3: 1848 | E3: 148 | F3: 148 | G3: 1642 | H3: 1287 | I3: 619 | J3: 1297 | K3: 619 | L3: 619 | M3: 1329 | N3: 1329 | S3: 378 | T3: 378 | Y3: 1218 | Z3: 1218
A4: SARL ferme du parc | B4: 1150
A5: Antoine Ferrera POPUP | B5: 8434 | G5: 5980 | H5: 5980 | K5: 4780 | L5: 4780
A6: Lefevre | B6: 56714 | C6: 20000 | D6: 19302 | E6: 15000 | F6: 30798 | G6: 3643 | H6: 2080 | K6: 2608 | L6: 2608
A7: Auber | B7: 39190 | G7: 14257 | H7: 14257 | I7: 15661 | J7: 15661 | K7: 1920 | L7: 1920 | Q7: 9272 | R7: 8693
A8: Poret Caval | B8: 1400 | C8: 1400 | D8: 1481
A9: Bouet | B9: 25254 | E9: 25254 | F9: 25254
A10: Hebert | B10: 20556 | G10: 7488 | H10: 7488 | K10: 6050 | L10: 6050 | M10: 7018 | N10: 6062
A11: Chérance | B11: 15550 | C11: 5000 | D11: 5296 | G11: 5000 | H11: 9024 | I11: 5550 | J11: 1178
A12: Regnault | B12: 27006 | G12: 8246 | H12: 8246 | I12: 6693 | J12: 6693 | K12: 9566 | L12: 9566
A13: PINCON | B13: 68041 | E13: 9261 | F13: 9261 | K13: 22548 | L13: 22548 | M13: 20466 | N13: 20466 | O13: 15766 | P13: 15766
A14: ROUILLE | B14: 21439 | E14: 5221 | F14: 5221 | I14: 1755 | J14: 1755 | K14: 11478 | L14: 11478 | M14: 2985 | N14: 3120
A15: ESNAULT | B15: 12722 | E15: 3885 | F15: 3885 | G15: 8837 | H15: 8837
A16: MALECOT | B16: 11800 | C16: 5000 | D16: 3540 | G16: 6800 | H16: 6800
A17: CARRE | B17: 14194 | S17: 4864 | T17: 4864 | Y17: 9330 | Z17: 9330
A18: LA TAVERNE | B18: 1050 | C18: 1050 | D18: 1053
A19: RAVENEL | B19: 31153 | S19: 10000 | T19: 10012 | U19: 15949 | V19: 15949 | Y19: 11533 | Z19: 11728
A20: APAEI | B20: 1550 | C20: 1550 | D20: 1550
A21: MARAIS
A22: RF JACQUELIN | B22: 7038 | C22: 7038 | D22: 7038
A23: RF JARDIN | B23: 20133 | K23: 2440 | L23: 2440 | O23: 17693 | P23: 17693
A24: DENIS Archiviolette | B24: 65528 | K24: 17967 | L24: 17967 | M24: 27033 | N24: 21802 | Q24: 20528 | R24: 22487
A25: CHAPRON | B25: 44827 | Q25: 8097 | R25: 8097 | U25: 23395 | V25: 23395 | Y25: 13335
A26: RF MELENNE | B26: 5170 | E26: 5170 | F26: 5170
A27: AASSGARD | B27: 400 | C27: 400 | D27: 400
A28: SCI LA JALOUSIE | B28: 6445 | C28: 2600 | D28: 2600 | K28: 3495 | L28: 3495
A29: SBTP BIHEL | B29: 7503 | S29: 7503 | T29: 7503
A30: VALDENAIRE | B30: 10588 | E30: 3940 | F30: 3940 | G30: 6648 | H30: 6648
A31: GRUAU | B31: 950 | G31: 950 | H31: 950
A32: RF LEMETTEIL | B32: 6400 | G32: 6400 | H32: 6400
A33: RF VICQUELIN | B33: 5523 | I33: 5523 | J33: 5523
A34: SCI GALOU | B34: 2177 | E34: 2177 | F34: 2177
A35: PRIGENT | B35: 275 | E35: 275 | F35: 275
A36: RF SEYMOUR | B36: 12000 | I36: 12000 | J36: 12293
A37: EARL FERME DU PARC | B37: 11798 | K37: 4379 | L37: 4379 | M37: 7419 | N37: 7419
A38: RF LESENECHAL | B38: 6835 | I38: 6835 | J38: 6835
A39: RF HGP | B39: 4375 | M39: 4375 | N39: 4375
A40: SARL ESNAULT LES MARINAS | B40: 47975 | O40: 16312 | P40: 16312 | Q40: 22782 | R40: 22782 | S40: 8880 | T40: 8880
...

Sheet 2016-17
C1: OCTOBRE | E1: NOVEMBRE | G1: DECEMBRE | I1: JANVIER | K1: FEVRIER | M1: MARS | O1: AVRIL | Q1: MAI | S1: JUIN | U1: JUILLET | W1: AOUT | Y1: SEPTEMBRE
A2: NOM | B2: CA/contrat | C2: prévu | D2: réalisé | E2: prévu | F2: réalisé | G2: prévu | H2: réalisé | I2: prévu | J2: réalisé | K2: prévu | L2: réalisé | M2: prévu | N2: réalisé | O2: prévu | P2: réalisé | Q2: prévu | R2: réalisé | S2: prévu | T2: réalisé | U2: prévu | V2: réalisé | W2: prévu | X2: réalisé | Y2: prévu | Z2: réalisé
A3: PASQUET commission
C5: 45000 | D5: 45000 | E5: 55000 | F5: 55000 | G5: 68000 | H5: 68000 | I5: 22000 | J5: 22000 | K5: 82000 | L5: 82000 | M5: 92000 | N5: 92000 | O5: 90000 | P5: 90000 | Q5: 92000 | R5: 92000 | S5: =30000+9000+15000+5000+15000+9000+5000+2400+4800+4000 -> 99200 | T5: 90000
A6: pasquet menuiseries | U6: 498 | V6: 498 | Y6: 1313 | Z6: 1313
A7: letourneur | B7: =74015-17000 -> 57015 | U7: 20000 | V7: 25578 | Y7: 15000 | Z7: 14337
A8: college sacre cœur | B8: 76016 | U8: 10000 | V8: 15000 | W8: 28000 | X8: 21816 | Y8: 0
A9: suard | B9: =1048+15880 -> 16928 | U9: 16928 | V9: 16928
A10: marie nadine | B10: 19445 | U10: 10000 | V10: 10946 | W10: 4500 | X10: 5637 | Y10: 2860 | Z10: 2860
A11: delahayes | B11: 12193 | U11: 10179 | V11: 10179 | Y11: 2014 | Z11: 2014
A12: poulain | B12: 30680 | Y12: 30684 | Z12: 30684
A13: cointo | B13: 3893 | Y13: 3893 | Z13: 3893
A14: hamon | B14: 4864 | Y14: 0
A15: cardet | B15: 3999 | Y15: 3999 | Z15: 3999
A16: le de | B16: 14352 | W16: 3240 | X16: 3847 | Y16: 0
A17: marie stephanie | B17: 39384 | Y17: 24817 | Z17: 24817
A18: hamel extension | B18: 27017 | Y18: 18609 | Z18: 18609
A19: hamel reno | B19: =7089+5638+7097 -> 19824 | U19: 7097 | V19: 12015 | Y19: 0
A20: defibat | B20: 6400 | W20: 6400 | X20: 6400
A21: huard | B21: 47234 | Y21: 13278 | Z21: 13278
A22: queron | B22: 102917
A23: james | B23: 31500
A24: peltier | B24: 228880
A25: perret | B25: 26120
A26: guiboux | B26: 92161
A27: lefevre | B27: 150000
A28: duquenoy | B28: 32915
A29: leclerc charp | B29: 7775
A30: bugenne | B30: 10191
A31: skrzypeck | B31: 14934 | Y31: 4000 | Z31: 4070 | AA31: TOTAL
AA35: TOTAL
A36: TOTAL CA mensuel prévu | B36: =SUM(B3:B35) -> 1076637 | C36: =SUM(C3:C35) -> 45000 | E36: =SUM(E3:E35) -> 55000 | G36: =SUM(G3:G35) -> 68000 | I36: =SUM(I3:I35) -> 22000 | K36: =SUM(K3:K35) -> 82000 | M36: =SUM(M3:M35) -> 92000 | O36: =SUM(O3:O35) -> 90000 | Q36: =SUM(Q3:Q35) -> 92000 | S36: =SUM(S3:S35) -> 99200 | U36: =SUM(U3:U35) -> 74702 | W36: =SUM(W3:W35) -> 42140 | Y36: =SUM(Y3:Y35) -> 120467 | AA36: =SUM(C36:Z36) -> 882509 | AB36: prévu
A37: TOTAL CA mensuel réalisé | D37: =SUM(D3:D36) -> 45000 | F37: =SUM(F3:F36) -> 55000 | H37: =SUM(H3:H36) -> 68000 | J37: =SUM(J3:J36) -> 22000 | L37: =SUM(L3:L36) -> 82000 | N37: =SUM(N3:N36) -> 92000 | P37: =SUM(P3:P36) -> 90000 | R37: =SUM(R3:R36) -> 92000 | T37: =SUM(T3:T36) -> 90000 | V37: =SUM(V3:V36) -> 91144 | X37: =SUM(X3:X36) -> 37700 | Z37: =SUM(Z3:Z36) -> 119874 | AA37: =SUM(C37:Z37) -> 884718 | AB37: réalisé
A38: TOTAL CA prévu cumulé | C38: =C36 -> 45000 | E38: =E36+C38 -> 100000 | G38: =G36+E38 -> 168000 | I38: =I36+G38 -> 190000 | K38: =K36+I38 -> 272000 | M38: =M36+K38 -> 364000 | O38: =O36+M38 -> 454000 | Q38: =Q36+O38 -> 546000 | S38: =S36+Q38 -> 645200 | U38: =U36+S38 -> 719902 | W38: =W36+U38 -> 762042 | Y38: =Y36+W38 -> 882509
A39: TOTAL CA réalisé cumulé | D39: =D37 -> 45000 | F39: =F37+D39 -> 100000 | H39: =H37+F39 -> 168000 | J39: =J37+H39 -> 190000 | L39: =L37+J39 -> 272000 | N39: =N37+L39 -> 364000 | P39: =P37+N39 -> 454000 | R39: =R37+P39 -> 546000 | T39: =T37+R39 -> 636000 | V39: =V37+T39 -> 727144 | X39: =X37+V39 -> 764844 | Z39: =Z37+X39 -> 884718
A43: Cumul CA réalisé 2015-16 | D43: 45886 | F43: 116217 | H43: 192108 | J43: 246744 | L43: 334594 | N43: 415103 | P43: 483292 | R43: 574139 | T43: 644265 | V43: 731112 | X43: 761055 | Z43: 842390
A44: Cumul CA réalisé 2016-17 | D44: =D39 -> 45000 | F44: =F39 -> 100000 | H44: =H39 -> 168000 | J44: =J39 -> 190000 | L44: =L39 -> 272000 | N44: =N39 -> 364000 | P44: =P39 -> 454000 | R44: =R39 -> 546000 | T44: =T39 -> 636000 | V44: =V39 -> 727144 | X44: =X39 -> 764844 | Z44: =Z39 -> 884718
A45: % évolution année n-1

Sheet 2017-18
D1: OCTOBRE | F1: NOVEMBRE | H1: DECEMBRE | J1: JANVIER | L1: FEVRIER | N1: MARS | P1: AVRIL | R1: MAI | T1: JUIN | V1: JUILLET | X1: AOUT | Z1: SEPTEMBRE
A2: NOM | B2: CA/contrat | C2: CA/prevision | D2: prévu | E2: réalisé | F2: prévu | G2: réalisé | H2: prévu | I2: réalisé | J2: prévu | K2: réalisé | L2: prévu | M2: réalisé | N2: prévu | O2: réalisé | P2: prévu | Q2: réalisé | R2: prévu | S2: réalisé | T2: prévu | U2: réalisé | V2: prévu | W2: réalisé | X2: prévu | Y2: réalisé | Z2: prévu | AA2: réalisé
A3: PASQUET commission | T3: 149.55 | U3: 149.55
A5: pasquet menuiseries | B5: 3164 | C5: 3164 | D5: 608 | E5: 608 | F5: 2375.31 | G5: 2375 | H5: 575.01 | I5: 575 | L5: 333 | M5: 333 | N5: 685 | O5: 685 | V5: =368.1+447.52+335.7+484.41+479.54+363.41 -> 2478.68 | W5: 2479
A6: letourneur | B6: 28591.66 | C6: =21791.66+6800 -> 28591.66 | D6: 0 | F6: 8000 | G6: 8000 | H6: =3288+3767 -> 7055 | I6: 7055 | J6: 6736 | K6: 6736 | P6: 6828 | Q6: 6828
A7: college sacre cœur | B7: =39850.23 -> 39850.23 | C7: 39850.23 | D7: 31322 | E7: 31322 | F7: 8528.01 | G7: 9057.18
A8: hamon | C8: 4864 | D8: 0 | E8: 0 | T8: 0
A9: le de | B9: =11642.56-3847.2 -> 7795.36 | C9: =11642.56-3847.2 -> 7795.36 | D9: 7795 | E9: 7795
A10: marie stephanie | B10: =39384.42-24817.18 -> 14567.24 | C10: =39384.42-24817.18 -> 14567.24 | D10: 12567 | E10: 12567 | F10: 2000 | G10: 2000
A11: hamel extension | B11: 14170 | C11: 14170 | F11: 9833 | G11: 9833 | H11: 2850 | I11: 2850
A12: hamel reno | B12: 6770 | C12: 6770 | F12: 6770 | G12: 6770
A13: huard | B13: =47234.29-13278.17 -> 33956.12 | C13: =47234.29-13278.17 -> 33956.12 | F13: 33956.22 | G13: 33956
A14: queron | B14: 102917.19 | C14: 102917.19 | F14: 14971 | G14: 14971 | J14: 0 | N14: 31989 | O14: 31989 | P14: 30990.1 | Q14: 30990.1 | R14: 11863.1 | S14: 11863 | T14: 7054 | U14: 7054 | V14: 6048 | W14: 6048
A15: james | B15: 26240 | C15: 26640 | H15: 5072 | I15: 5072 | J15: 0 | L15: 6722 | M15: 6722 | N15: 4673 | O15: 4673 | P15: 8090 | Q15: 8090 | T15: 2082 | U15: 2082
A16: peltier | B16: 256701 | C16: 256701 | D16: 56000 | E16: 56000 | F16: 0 | H16: 45000 | I16: 45000 | J16: 0 | L16: 51027 | M16: 51027 | N16: 13901 | O16: 13901 | P16: 0 | Q16: 0 | R16: 26817.63 | S16: 26818 | T16: =26223+7269 -> 33492 | U16: 33492 | V16: 20069.23 | W16: 20069.23 | X16: 4048 | Z16: 10000
A17: perree | B17: 22450 | C17: 22450 | F17: 0 | H17: 6735 | I17: 6735 | J17: 0 | L17: 15715 | M17: 15715
A18: guiboux | C18: 92161.48
A19: lefevre | C19: 149882.03
A20: duquenoy | C20: =58285.49+10077.21 -> 68362.7
A21: De Souza | B21: 7392.42 | C21: =B21 -> 7392.42 | H21: 0 | L21: 7392 | M21: 7392
A22: bugenne | B22: 10191 | C22: 10191 | H22: 0 | J22: 0 | L22: 0 | T22: 10191 | U22: 10191
A23: skrzypeck | B23: =14189.06-4000 -> 10189.06 | C23: =14189.06-4000 -> 10189.06 | F23: 5390 | G23: 5390 | H23: 4614 | I23: 4614 | J23: 0
A24: henry ifs | B24: 27194.72 | C24: 27194.72 | F24: 0 | H24: 27194 | I24: 27194 | J24: 0
A25: desnos | B25: 9838 | C25: 9838 | H25: 9838 | I25: 9838
A26: mickaelis | B26: 31084 | C26: 31084 | F26: 5111 | G26: 5111 | H26: 25973 | I26: 25973
A27: bacon | B27: 36487 | C27: 36487 | N27: 0 | P27: 14404 | Q27: 14404 | R27: 15574 | S27: 15574 | T27: 0 | V27: =2900+3200 -> 6100 | W27: 6100
A28: hoste | B28: 55000 | C28: 55000 | F28: 0 | H28: 11238 | I28: 11238 | J28: 0 | L28: 30431 | M28: 30431 | N28: 13329 | O28: 13329
A29: louiche | B29: =C29 -> 14947 | C29: 14947 | P29: 3924 | Q29: 3924 | T29: 11023 | U29: 11023 | AB29: TOTAL
A30: rf goubin | B30: 1500 | C30: 1500 | J30: 0 | N30: 1500 | O30: 1500
A31: patrignani | B31: 3176 | C31: =B31 -> 3176 | D31: 3171 | E31: 3171
A32: FAUNY | B32: 20037.29 | C32: 20037.29 | N32: 11789 | O32: 11789 | P32: 8248 | Q32: 8248
A33: JARDIN via C. CABARET | C33: 122716.9
A34: crosfit | B34: 1000 | C34: 1000 | P34: 1000 | Q34: 1000
A35: rf ablin | B35: 10956 | C35: 10956 | P35: 10956 | Q35: 10956
A36: pezant | B36: 2484 | C36: 2484 | N36: 2484 | O36: 2484
A37: Rousseau | B37: 44277 | C37: 44277 | R37: 11580.24 | S37: 11580 | T37: 10812.39 | U37: 10812.39 | V37: 18998.89 | W37: 18998.89 | X37: 1938 | Z37: 947
A38: thomann | B38: 4085 | C38: 4085 | N38: 4085 | O38: 4085
A39: Gabriel | B39: 65791.68 | C39: =B39 -> 65791.68 | P39: 0 | R39: 20315.52 | S39: 20316 | T39: 0 | V39: 13168.94 | W39: 13168.94 | X39: 9897 | Z39: 10000
A40: ccs international | B40: 8232 | C40: 8232 | T40: 8232 | U40: 8232
A41: lequitte | B41: 790.4 | C41: 790.4 | L41: 790 | M41: 790
...

Sheet 2018-19
D1: OCTOBRE | F1: NOVEMBRE | H1: DECEMBRE | J1: JANVIER | L1: FEVRIER | N1: MARS | P1: AVRIL | R1: MAI | T1: JUIN | V1: JUILLET | X1: AOUT | Z1: SEPTEMBRE
A2: NOM | B2: CA/contrat | C2: CA/prevision | D2: prévu | E2: réalisé | F2: prévu | G2: réalisé | H2: prévu | I2: réalisé | J2: prévu | K2: réalisé | L2: prévu | M2: réalisé | N2: prévu | O2: réalisé | P2: prévu | Q2: réalisé | R2: prévu | S2: réalisé | T2: prévu | U2: réalisé | V2: prévu | W2: réalisé | X2: prévu | Y2: réalisé | Z2: prévu | AA2: réalisé
A3: PASQUET commission | V3: 145 | W3: 145 | Z3: =916.9+1570 -> 2486.9 | AA3: =917+1570 -> 2487
A4: Commission ST | B4: 422 | C4: 422 | N4: 422 | O4: 422 | V4: =143+578 -> 721 | W4: 721 | X4: 578 | Y4: 578 | Z4: 738 | AA4: 738
A5: pasquet menuiseries
A6: PELTIER | B6: 7082 | C6: 7082 | F6: 0 | H6: 0 | J6: 0 | N6: 7562 | O6: 7562
A7: MORLET blonville sur mer | B7: 47889 | C7: =112.89+47776 -> 47888.89 | F7: 33590 | G7: 33590 | H7: 937 | I7: 937 | J7: =112.89+13217 -> 13329.89 | K7: 13330
A8: QUEMENER | B8: 25132 | C8: 25132 | D8: 0 | F8: 0 | H8: 10969 | I8: 10969 | J8: 14163 | K8: 14163
A9: GOULAIN | B9: 15973 | C9: 15973 | D9: 10333 | E9: 10333 | J9: 0 | L9: 3398 | M9: 3398 | N9: 0
A10: GUIBOUT | B10: =71065+5867 -> 76932 | C10: =71065+5867 -> 76932 | D10: 0 | F10: 0 | H10: 15997 | I10: 15997 | J10: 20524 | K10: 20524 | N10: 15454 | O10: 15454 | P10: 10336 | Q10: 10336 | Z10: =5871+5867 -> 11738 | AA10: =5871+5867 -> 11738
A11: GABRIEL | B11: 11184 | C11: 11184 | D11: 0 | F11: 0 | H11: 10592 | I11: 10592 | J11: 0 | N11: =382.54+1026.93 -> 1409.47 | O11: 1409
A12: GERMAIN | B12: 136516 | C12: 136516 | H12: 21166 | I12: 21166 | J12: 29539 | K12: 29539 | N12: 33628 | O12: 33628 | P12: 30034 | Q12: 30034 | R12: 6094.4 | S12: 6094 | T12: 11020 | U12: 11020 | V12: 5035 | W12: 5035
A13: LEDORZE | B13: 9088 | C13: =5603.29+3485 -> 9088.29 | D13: 9088 | E13: 9088
A14: SCI IFL | B14: 4967 | C14: 4967 | D14: 4967 | E14: 4967 | AB14: TOTAL
A15: SARL LA FOURNEE | C15: 7697 | F15: 0
A16: FERARD | B16: 52246 | C16: 52246 | F16: 0 | J16: 6265 | K16: 6265 | N16: 24109 | O16: 24109 | P16: 15667 | Q16: 15667
A18: SCI DES MOTTETS | B18: 10544 | C18: 10544 | H18: 4004 | I18: 4004 | J18: =5966.85+298.57+274.49 -> 6539.91 | K18: 6540
A19: MOREL | C19: 128702
A22: TALMAR | B22: 6420 | C22: 6420 | F22: 6420 | G22: 6420
A23: FOUREY | B23: 3963 | C23: 3963 | N23: 3963 | O23: 3963
A24: CHAMPION | B24: 1620 | C24: 1620 | D24: 1042 | E24: 1042 | J24: 0 | R24: 1620 | S24: 1620
A25: PAPILLON | B25: 16756 | C25: 16756 | J25: 3032.54 | K25: 3033 | N25: 13723 | O25: 13723
A26: LOPEZ | B26: 4221 | C26: 4221 | J26: 4221 | K26: 4221
A27: MANCHE | B27: 62896 | C27: 62896 | R27: 18868 | S27: 18868 | T27: 0 | V27: 19393 | W27: 19393 | Z27: 22852 | AA27: 22852
A28: MOROTTI | B28: 8451 | C28: 8451 | D28: 0 | F28: 8451 | G28: 8451
A29: DEFLIN | B29: 1372.46 | C29: 1372.46 | D29: 1372 | E29: 1372
F30: 0
A31: ESTORGES | B31: 1337 | C31: 1337 | F31: 0 | H31: 1337 | I31: 1337
A32: LASTELLE | B32: 29492 | C32: 29492 | J32: 9558 | K32: 9558 | N32: 19934 | O32: 19934
A33: VERGRIETE | B33: 50956 | C33: 50956 | X33: 14207 | Y33: 14207 | Z33: 0
A34: MARIE | B34: 81382 | C34: 81382 | X34: 15242 | Y34: 15242 | Z34: 14391 | AA34: 14391
A35: KITE SURF | C35: 54304 | Z35: 0
A36: GIRARD | C36: 79325
A38: CADIEU NOURY | C38: 86613
A39: FLAGUAIS | B39: 42611 | C39: 42611 | N39: 11365 | O39: 11365 | R39: 21018 | S39: 21018 | X39: 10226 | Y39: 10226
A40: BOUET | B40: 5336 | C40: =4056+1280 -> 5336 | L40: 5336 | M40: 5336
A41: DLH | C41: 26000
A42: JOLY | B42: 1438 | C42: 1438 | L42: 1438 | M42: 1438
A43: NOGENT | B43: 19583 | C43: 19583 | T43: 9463.47 | U43: 9463 | V43: 10119 | W43: 10119
A44: DARDE | B44: 31830 | C44: 31830 | R44: 10720 | S44: 10720 | T44: 14992 | U44: 14992 | V44: 4418 | W44: 4418
...

Sheet 2019-20
E1: OCTOBRE | G1: NOVEMBRE | I1: DECEMBRE | K1: JANVIER | M1: FEVRIER | O1: MARS | Q1: AVRIL | S1: MAI | U1: JUIN | W1: JUILLET | Y1: AOUT | AA1: SEPTEMBRE
A2: NOM | C2: CA/contrat | D2: CA/prevision | E2: prévu | F2: réalisé | G2: prévu | H2: réalisé | I2: prévu | J2: réalisé | K2: prévu | L2: réalisé | M2: prévu | N2: réalisé | O2: prévu | P2: réalisé | Q2: prévu | R2: réalisé | S2: prévu | T2: réalisé | U2: prévu | V2: réalisé | W2: prévu | X2: réalisé | Y2: prévu | Z2: réalisé | AA2: prévu | AB2: réalisé
A3: Commission PASQUET | C3: =882+300+1211 -> 2393 | D3: =882+300+1211 -> 2393 | G3: =423+459 -> 882 | H3: 882 | K3: 300 | L3: 300 | M3: 1211.1 | N3: 1211.1 | Q3: 715.41 | R3: 715.41 | U3: =276.26+1078.87 -> 1355.13 | V3: 1355 | AA3: 1334.3 | AB3: 1334.3
A4: Commission ST | C4: =1231+1000+564 -> 2795 | D4: 2795 | I4: 1000 | J4: 1000 | K4: 1230.87 | L4: 1230.87 | M4: 564.03 | N4: 564.03 | Q4: =988.4+183.02 -> 1171.42 | R4: 1171 | S4: =132.5+262.38 -> 394.88 | T4: 395 | W4: 934 | X4: 934
A6: GERNAULT - IBANESCU | D6: 97245 | AC6: =D6-U6-W6-Y6-AA6 -> 97245
A7: SCHIEL | D7: 137101 | AC7: =D7-U7-W7-Y7-AA7 -> 137101
A8: GEZE | D8: 46977 | AC8: =D8-U8-W8-Y8-AA8 -> 46977
A9: THIRE | D9: 45339 | AC9: =D9-U9-W9-Y9-AA9 -> 45339
A10: LEROULLIER | C10: 43205 | D10: 43205 | AC10: =D10-U10-W10-Y10-AA10 -> 43205
A11: CHESNEL | C11: 23403 | D11: 23403 | AC11: =D11-U11-W11-Y11-AA11 -> 23403
A12: RF ROUSSEL | C12: 51345 | D12: 51345 | AC12: =D12-U12-W12-Y12-AA12 -> 51345
A13: JAGER | C13: 70682 | D13: 70682 | AC13: =D13-U13-W13-Y13-AA13 -> 70682
A14: HULIN | C14: 35372 | D14: 35372.24 | AC14: =D14-U14-W14-Y14-AA14 -> 35372.24
A15: DARCILLON | D15: 68020 | AC15: =D15-U15-W15-Y15-AA15 -> 68020
A16: LALLOZ | C16: 4865.8 | D16: 4865.8 | AC16: 4865.8
A17: FROGER | C17: 1913 | D17: 1913 | AC17: 1913.88
A18: ROUILLARD | C18: 11993.73 | D18: 11993.73 | AC18: =D18-U18-W18-Y18-AA18 -> 11993.73
A19: BICARD | C19: 13428 | D19: 13428 | AC19: =D19-U19-W19-Y19-AA19 -> 13428
A20: BOEUVE | C20: 22297 | D20: 22297 | AC20: =D20-U20-W20-Y20-AA20 -> 22297
A21: GERMAIN | C21: 2019 | D21: 2019 | AC21: =D21-U21-W21-Y21-AA21 -> 2019
A22: ROUSSEL | C22: 86048 | D22: 86048 | Y22: 14221.6 | Z22: 14222 | AC22: =D22-U22-W22-Y22-AA22 -> 71826.4
A23: RF FLIPO | C23: 12911 | D23: 12911 | O23: 6053.31 | P23: 6053.31 | S23: 2073 | T23: 2073 | AC23: =D23-O23-S23-U23-W23-Y23-AA23 -> 4784.69
A24: SHACHER | C24: 35629 | D24: 35629.01 | W24: 9593.87 | X24: 9593.87 | AC24: =D24-U24-W24-Y24-AA24 -> 26035.14
A25: LEVEQUE GARAGE | C25: 16424.62 | D25: 16424.62 | W25: 3012.79 | X25: 3012.79 | AC25: =D25-U25-W25-Y25-AA25 -> 13411.83
A26: LEVEQUE | C26: =56621.6+90 -> 56711.6 | D26: =56621.6+90 -> 56711.6 | I26: =27727.11+2871.46 -> 30598.57 | J26: 30599 | K26: =5116.74+1825.21 -> 6941.95 | L26: 6942 | M26: 14328.36 | N26: 14328 | W26: =1260+3582.72 -> 4842.72 | X26: 4843 | AC26: =D26-I26-K26-M26-U26-W26-Y26-AA26 -> -1.8189894e-12
A27: DAGORN | C27: 60469 | D27: 60469 | W27: 18141.35 | X27: 18141.35 | AC27: =D27-U27-W27-Y27-AA27 -> 42327.65
A28: CAUCE via joris cenier | C28: 20274 | D28: 20274 | W28: 5109.75 | X28: 5109.75 | AC28: =D28-U28-W28-Y28-AA28 -> 15164.25
A29: DARDE | C29: =1700+2657 -> 4357 | D29: 4357 | S29: 2657.57 | T29: 2658 | AC29: =D29-S29-U29-W29-Y29-AA29 -> 1699.43
A30: BRODIN | C30: 27757 | D30: 27757 | Y30: 6161.14 | Z30: 6161.14 | AA30: 7658.33 | AB30: 7658.06 | AC30: =D30-U30-W30-Y30-AA30 -> 13937.53
A31: JOUAULT | C31: 21815.39 | D31: 21815.39 | AA31: 5291.09 | AB31: 5291.09 | AC31: =D31-U31-W31-Y31-AA31 -> 16524.3
A32: CHAUVEL | C32: 77453 | D32: 77453 | Y32: 15033.91 | Z32: 15034 | AA32: 18933.43 | AB32: 18933.43 | AC32: =D32-U32-W32-Y32-AA32 -> 43485.66
A33: SCI WATIER | C33: 36413 | D33: 36413 | AA33: =18113.56+11560.07 -> 29673.63 | AB33: =11560.07+18113.56 -> 29673.63 | AC33: =D33-U33-W33-Y33-AA33 -> 6739.37
A34: COYER | C34: =32007+368.45 -> 32375.45 | D34: 32375 | S34: 5652.23 | T34: 5652 | W34: 7196.88 | X34: 7197 | Y34: 5944.21 | Z34: 5944.21 | AA34: =6194.32+368.45 -> 6562.77 | AB34: 6563 | AC34: =D34-S34-U34-W34-Y34-AA34 -> 7018.91
A35: CADIEU NOURY | C35: =88130-2411.28+1388.91 -> 87107.63 | D35: =88130+1388.91-2411.28 -> 87107.63 | G35: 9456 | H35: 9456 | I35: 18664 | J35: 18664 | K35: 16738 | L35: 16737.55 | M35: 12574.17 | N35: 12574.17 | O35: 5332.53 | P35: 5332.53 | U35: 18992 | V35: 18992 | W35: 3425 | X35: 3425 | AA35: =D35-X35-V35-P35-N35-L35-J35-H35 -> 1926.38 | AB35: 1926 | AC35: =D35-G35-I35-K35-M35-O35-Q35-S35-U35-W35-Y35-AA35 -> -0.45
A36: MAINCENT | C36: 28887 | D36: 28887 | S36: 7157.29 | T36: 7157 | U36: 4298 | V36: 4298 | W36: 4501.84 | X36: 4502 | AA36: 12930 | AB36: 12930 | AC36: =D36-S36-U36-W36-Y36-AA36 -> -0.13
A37: SINIGAGLIA | C37: =17182+2877.27 -> 20059.27 | D37: =17182+2877.27 -> 20059.27 | U37: 9488 | V37: 9488 | W37: =14102.37-U37 -> 4614.37 | X37: 4614 | AA37: =3080+2877.27 -> 5957.27 | AB37: 5957 | AC37: =D37-U37-W37-Y37-AA37 -> -0.37
A38: RAOULT | C38: =106191.06+1844.06 -> 108035.12 | D38: 108035 | S38: 31760.01 | T38: 31760 | U38: 31208 | V38: 31208 | W38: 40428.81 | X38: 40429 | AA38: =D38-T38-V38-X38 -> 4638 | AB38: 4638 | AC38: =D38-S38-U38-W38-Y38-AA38 -> 0.18
A39: TESSON | C39: =68578+4726 -> 73304 | D39: 73304 | G39: 8735.21 | H39: 8735 | I39: 12421 | J39: 12421 | K39: 4746 | L39: 4746.41 | M39: 40465 | N39: 40465 | W39: =6937-9618.45 -> -2681.45 | X39: -2681 | AA39: =2964+1029.91 -> 3993.91 | AB39: 3994 | AC39: cee | AD39: 11500
A40: MAHE | C40: 458.33 | D40: 458.33 | AA40: 458 | AB40: 458
A41: EXAEQUO | C41: 1500 | D41: 1500 | AA41: 1500 | AB41: 1500
...

Sheet 2020-21
F4: OSSATURE | G4: OB | H4: CHARPENTE | I4: CB | J4: MENUISERIE | K4: MX | L4: BARDAGE | M4: BA | N4: ISOLATION | O4: IEA | P4: PLATRERIE | Q4: PII | R4: DIVERS | S4: DIV | U4: OCTOBRE | W4: NOVEMBRE | Y4: DECEMBRE | AA4: JANVIER | AC4: FEVRIER | AE4: MARS | AG4: AVRIL | AI4: MAI | AK4: JUIN | AM4: JUILLET | AO4: AOUT | AQ4: SEPTEMBRE
A5: NOM | C5: CA/prevision | D5: CA/contrat | F5: BOIS | G5: % | H5: BOIS | I5: % | J5: EXTERIEURE | K5: % | L5: EXT | M5: % | N5: ETANCHEITE | O5: % | P5: ISO INT MI | Q5: % | S5: % | U5: prévu | V5: réalisé | W5: prévu | X5: réalisé | Y5: prévu | Z5: réalisé | AA5: prévu | AB5: réalisé | AC5: prévu | AD5: réalisé | AE5: prévu | AF5: réalisé | AG5: prévu | AH5: réalisé | AI5: prévu | AJ5: réalisé | AK5: prévu | AL5: réalisé | AM5: prévu | AN5: réalisé | AO5: prévu | AP5: réalisé | AQ5: prévu | AR5: réalisé | AS5: 2021/2022
A7: Commission PASQUET | Y7: =1520.96 -> 1520.96 | Z7: =1520.96 -> 1520.96 | AI7: -608.7 | AJ7: -608.7
A8: Commission PASQUET | AI8: -1344.3 | AJ8: -1344
A9: Commission PASQUET | AI9: 855 | AJ9: 855
A10: Commission PASQUET | AI10: 608.7 | AJ10: 608.7
A11: Commission ST
A12: loret avoir | AI12: -564 | AJ12: -564
G13: =F13/E13 -> #DIV/0! | I13: =H13/E13 -> #DIV/0! | K13: =J13/E13 -> #DIV/0! | M13: =L13/E13 -> #DIV/0! | O13: =N13/E13 -> #DIV/0! | Q13: =P13/E13 -> #DIV/0! | S13: =R13/E13 -> #DIV/0! | T13: =S13+Q13+O13+M13+K13+I13+G13 -> #DIV/0! | AA13: =D13-U13-W13-Y13 -> 0 | AC13: =D13-U13-W13-Y13-AA13 -> 0 | AE13: =D13-U13-W13-Y13-AA13-AC13 -> 0 | AG13: =D13-U13-W13-Y13-AA13-AC13-AE13 -> 0 | AI13: =D13-U13-W13-Y13-AA13-AC13-AE13-AG13 -> 0 | AK13: =D13-U13-W13-Y13-AA13-AC13-AE13-AG13-AI13 -> 0 | AM13: =D13-U13-W13-Y13-AA13-AC13-AE13-AG13-AI13-AK13 -> 0 | AO13: =D13-U13-W13-Y13-AA13-AC13-AE13-AG13-AI13-AK13-AM13 -> 0 | AQ13: =D13-U13-W13-Y13-AA13-AC13-AE13-AG13-AI13-AK13-AM13-AO13 -> 0 | AS13: =D13-U13-W13-Y13-AA13-AC13-AE13-AG13-AI13-AK13-AM13-AO13-AQ13 -> 0
G14: =F14/E14 -> #DIV/0! | I14: =H14/E14 -> #DIV/0! | K14: =J14/E14 -> #DIV/0! | M14: =L14/E14 -> #DIV/0! | O14: =N14/E14 -> #DIV/0! | Q14: =P14/E14 -> #DIV/0! | S14: =R14/E14 -> #DIV/0! | T14: =S14+Q14+O14+M14+K14+I14+G14 -> #DIV/0! | AA14: =D14-U14-W14-Y14 -> 0 | AC14: =D14-U14-W14-Y14-AA14 -> 0 | AE14: =D14-U14-W14-Y14-AA14-AC14 -> 0 | AG14: =D14-U14-W14-Y14-AA14-AC14-AE14 -> 0 | AI14: =D14-U14-W14-Y14-AA14-AC14-AE14-AG14 -> 0 | AK14: =D14-U14-W14-Y14-AA14-AC14-AE14-AG14-AI14 -> 0 | AM14: =D14-U14-W14-Y14-AA14-AC14-AE14-AG14-AI14-AK14 -> 0 | AO14: =D14-U14-W14-Y14-AA14-AC14-AE14-AG14-AI14-AK14-AM14 -> 0 | AQ14: =D14-U14-W14-Y14-AA14-AC14-AE14-AG14-AI14-AK14-AM14-AO14 -> 0 | AS14: =D14-U14-W14-Y14-AA14-AC14-AE14-AG14-AI14-AK14-AM14-AO14-AQ14 -> 0
G15: =F15/E15 -> #DIV/0! | I15: =H15/E15 -> #DIV/0! | K15: =J15/E15 -> #DIV/0! | M15: =L15/E15 -> #DIV/0! | O15: =N15/E15 -> #DIV/0! | Q15: =P15/E15 -> #DIV/0! | S15: =R15/E15 -> #DIV/0! | T15: =S15+Q15+O15+M15+K15+I15+G15 -> #DIV/0! | AA15: =D15-U15-W15-Y15 -> 0 | AC15: =D15-U15-W15-Y15-AA15 -> 0 | AE15: =D15-U15-W15-Y15-AA15-AC15 -> 0 | AG15: =D15-U15-W15-Y15-AA15-AC15-AE15 -> 0 | AI15: =D15-U15-W15-Y15-AA15-AC15-AE15-AG15 -> 0 | AK15: =D15-U15-W15-Y15-AA15-AC15-AE15-AG15-AI15 -> 0 | AM15: =D15-U15-W15-Y15-AA15-AC15-AE15-AG15-AI15-AK15 -> 0 | AO15: =D15-U15-W15-Y15-AA15-AC15-AE15-AG15-AI15-AK15-AM15 -> 0 | AQ15: =D15-U15-W15-Y15-AA15-AC15-AE15-AG15-AI15-AK15-AM15-AO15 -> 0 | AS15: =D15-U15-W15-Y15-AA15-AC15-AE15-AG15-AI15-AK15-AM15-AO15-AQ15 -> 0
A16: MARTINS | C16: 23433.53 | D16: 23433.53 | F16: =5274.01+900 -> 6174.01 | G16: =F16/E16 -> #DIV/0! | H16: 1870.13 | I16: =H16/E16 -> #DIV/0! | J16: 3332.67 | K16: =J16/E16 -> #DIV/0! | L16: 6800.94 | M16: =L16/E16 -> #DIV/0! | N16: 1406.23 | O16: =N16/E16 -> #DIV/0! | P16: 2475.19 | Q16: =P16/E16 -> #DIV/0! | R16: =976.86+397.5 -> 1374.36 | S16: =R16/E16 -> #DIV/0! | T16: =S16+Q16+O16+M16+K16+I16+G16 -> #DIV/0! | AA16: 0 | AC16: 0 | AE16: 0 | AG16: 0 | AI16: 0 | AK16: 0 | AM16: 0 | AO16: 0 | AQ16: 0 | AS16: =D16-U16-W16-Y16-AA16-AC16-AE16-AG16-AI16-AK16-AM16-AO16-AQ16 -> 23433.53
A17: Mairie de MOULT | C17: 22356.5 | D17: 22357 | G17: =F17/E17 -> #DIV/0! | H17: =900+18576.5 -> 19476.5 | I17: =H17/E17 -> #DIV/0! | K17: =J17/E17 -> #DIV/0! | M17: =L17/E17 -> #DIV/0! | O17: =N17/E17 -> #DIV/0! | Q17: =P17/E17 -> #DIV/0! | R17: =1440+1440 -> 2880 | S17: =R17/E17 -> #DIV/0! | T17: =S17+Q17+O17+M17+K17+I17+G17 -> #DIV/0! | AA17: 0 | AC17: 0 | AE17: 0 | AG17: 0 | AI17: 0 | AK17: 0 | AM17: 0 | AO17: 0 | AQ17: 0 | AS17: =D17-U17-W17-Y17-AA17-AC17-AE17-AG17-AI17-AK17-AM17-AO17-AQ17 -> 22357
A18: CROCHARD | C18: 20600 | D18: 20600 | G18: =F18/E18 -> #DIV/0! | H18: =4263.46+857.31+744 -> 5864.77 | I18: =H18/E18 -> #DIV/0! | J18: 2638.69 | K18: =J18/E18 -> #DIV/0! | M18: =L18/E18 -> #DIV/0! | O18: =N18/E18 -> #DIV/0! | Q18: =P18/E18 -> #DIV/0! | R18: 12602.14 | S18: =R18/E18 -> #DIV/0! | T18: =S18+Q18+O18+M18+K18+I18+G18 -> #DIV/0! | AA18: 0 | AC18: 0 | AE18: 0 | AG18: 0 | AI18: 0 | AK18: 0 | AM18: 0 | AO18: 0 | AQ18: 0 | AS18: =D18-U18-W18-Y18-AA18-AC18-AE18-AG18-AI18-AK18-AM18-AO18-AQ18 -> 20600
A19: HERBLOT | C19: 61500 | D19: 61500 | F19: =900+10152.75 -> 11052.75 | G19: =F19/E19 -> #DIV/0! | H19: 11036.29 | I19: =H19/E19 -> #DIV/0! | J19: 8633.38 | K19: =J19/E19 -> #DIV/0! | L19: 12184.11 | M19: =L19/E19 -> #DIV/0! | N19: 3363.76 | O19: =N19/E19 -> #DIV/0! | P19: 15203.61 | Q19: =P19/E19 -> #DIV/0! | S19: =R19/E19 -> #DIV/0! | T19: =S19+Q19+O19+M19+K19+I19+G19 -> #DIV/0! | AA19: 0 | AC19: 0 | AE19: 0 | AG19: 0 | AI19: 0 | AK19: 0 | AM19: 0 | AO19: 0 | AQ19: 0 | AS19: =D19-U19-W19-Y19-AA19-AC19-AE19-AG19-AI19-AK19-AM19-AO19-AQ19 -> 61500
A20: JAGER | C20: 81301.93 | D20: =C20 -> 81301.93 | E20: 14288.15 | F20: =11033.19+1450 -> 12483.19 | G20: =F20/E20 -> 0.87367434 | H20: 1904.96 | I20: =H20/E20 -> 0.13332447 | K20: =J20/E20 -> 0 | M20: =L20/E20 -> 0 | O20: =N20/E20 -> 0 | Q20: =P20/E20 -> 0 | S20: =R20/E20 -> 0 | T20: =S20+Q20+O20+M20+K20+I20+G20 -> 1.0069988 | AA20: 0 | AC20: 0 | AE20: 0 | AG20: 0 | AI20: 0 | AK20: 0 | AM20: 0 | AO20: 0 | AQ20: 14288 | AR20: 14288.15 | AS20: =D20-U20-W20-Y20-AA20-AC20-AE20-AG20-AI20-AK20-AM20-AO20-AQ20 -> 67013.93
A21: LEMOINE | C21: 42665 | D21: 42665 | E21: 42665 | G21: =F21/E21 -> 0 | I21: =H21/E21 -> 0 | J21: 42665 | K21: =J21/E21 -> 1 | M21: =L21/E21 -> 0 | O21: =N21/E21 -> 0 | Q21: =P21/E21 -> 0 | S21: =R21/E21 -> 0 | T21: =S21+Q21+O21+M21+K21+I21+G21 -> 1 | AA21: 0 | AC21: 0 | AE21: 0 | AG21: 0 | AI21: 0 | AK21: 0 | AM21: 33471 | AN21: 33471 | AO21: =D21-U21-W21-Y21-AA21-AC21-AE21-AG21-AI21-AK21-AM21 -> 9194 | AP21: 9194 | AQ21: =D21-U21-W21-Y21-AA21-AC21-AE21-AG21-AI21-AK21-AM21-AO21 -> 0 | AS21: =D21-U21-W21-Y21-AA21-AC21-AE21-AG21-AI21-AK21-AM21-AO21-AQ21 -> 0
A22: FRANCOIS | C22: 52084 | D22: 52084 | E22: 12354.85 | F22: =900+4011.91 -> 4911.91 | G22: =F22/E22 -> 0.39756938 | H22: 1141.89 | I22: =H22/E22 -> 0.092424433 | J22: 2216.25 | K22: =J22/E22 -> 0.179383 | L22: 4084.8 | M22: =L22/E22 -> 0.3306232 | O22: =N22/E22 -> 0 | Q22: =P22/E22 -> 0 | S22: =R22/E22 -> 0 | T22: =S22+Q22+O22+M22+K22+I22+G22 -> 1 | AA22: 0 | AC22: 0 | AE22: 0 | AG22: 0 | AI22: 0 | AK22: 0 | AM22: 0 | AQ22: 12355 | AR22: 12354.85 | AS22: =D22-U22-W22-Y22-AA22-AC22-AE22-AG22-AI22-AK22-AM22-AO22-AQ22 -> 39729
A23: CUVIGNY | C23: 18000 | D23: 18000 | E23: 18000 | F23: 8184 | G23: =F23/E23 -> 0.45466667 | H23: 1603 | I23: =H23/E23 -> 0.089055556 | J23: 2235 | K23: =J23/E23 -> 0.12416667 | L23: 4557 | M23: =L23/E23 -> 0.25316667 | N23: 1426 | O23: =N23/E23 -> 0.079222222 | Q23: =P23/E23 -> 0 | S23: =R23/E23 -> 0 | T23: =S23+Q23+O23+M23+K23+I23+G23 -> 1.0002778 | AA23: 0 | AC23: 0 | AE23: 0 | AG23: 0 | AI23: 0 | AK23: 4767.92 | AL23: 4767.92 | AM23: 4849 | AN23: 4849.37 | AO23: 0 | AQ23: =D23-U23-W23-Y23-AA23-AC23-AE23-AG23-AI23-AK23-AM23-AO23 -> 8383.08 | AR23: 8382.71 | AS23: =D23-U23-W23-Y23-AA23-AC23-AE23-AG23-AI23-AK23-AM23-AO23-AQ23 -> 0
A24: BASSIERE | C24: 25682.67 | D24: 25682.67 | E24: 25683 | F24: 8586 | G24: =F24/E24 -> 0.33430674 | H24: 1603 | I24: =H24/E24 -> 0.062414827 | J24: 5901 | K24: 0 | L24: 8165 | M24: =L24/E24 -> 0.31791457 | N24: 1426 | O24: =N24/E24 -> 0.055523109 | Q24: =P24/E24 -> 0 | S24: =R24/E24 -> 0 | T24: =S24+Q24+O24+M24+K24+I24+G24 -> 0.77015925 | AA24: 0 | AC24: 0 | AE24: 0 | AG24: 0 | AI24: 0 | AK24: 6332.4 | AL24: 6332.4 | AM24: 5465 | AN24: 5464.8 | AO24: 0 | AQ24: =D24-U24-W24-Y24-AA24-AC24-AE24-AG24-AI24-AK24-AM24-AO24 -> 13885.27 | AR24: 13885.47 | AS24: =D24-U24-W24-Y24-AA24-AC24-AE24-AG24-AI24-AK24-AM24-AO24-AQ24 -> 0
A25: EXAEQUO | C25: 533.33 | D25: 533.33 | E25: 533 | G25: =F25/E25 -> 0 | I25: =H25/E25 -> 0 | K25: =J25/E25 -> 0 | M25: =L25/E25 -> 0 | O25: =N25/E25 -> 0 | Q25: =P25/E25 -> 0 | R25: 533 | S25: =R25/E25 -> 1 | T25: =S25+Q25+O25+M25+K25+I25+G25 -> 1 | AA25: 0 | AC25: 0 | AE25: 0 | AG25: 533.33 | AH25: 533.33 | AI25: =D25-U25-W25-Y25-AA25-AC25-AE25-AG25 -> 0 | AK25: =D25-U25-W25-Y25-AA25-AC25-AE25-AG25-AI25 -> 0 | AM25: =D25-U25-W25-Y25-AA25-AC25-AE25-AG25-AI25-AK25 -> 0 | AO25: =D25-U25-W25-Y25-AA25-AC25-AE25-AG25-AI25-AK25-AM25 -> 0 | AQ25: =D25-U25-W25-Y25-AA25-AC25-AE25-AG25-AI25-AK25-AM25-AO25 -> 0 | AS25: =D25-U25-W25-Y25-AA25-AC25-AE25-AG25-AI25-AK25-AM25-AO25-AQ25 -> 0
A26: PREVOST | C26: 1821 | D26: 1821 | E26: 1821 | G26: =F26/E26 -> 0 | I26: =H26/E26 -> 0 | K26: =J26/E26 -> 0 | M26: =L26/E26 -> 0 | O26: =N26/E26 -> 0 | Q26: =P26/E26 -> 0 | R26: 1821 | S26: =R26/E26 -> 1 | T26: =S26+Q26+O26+M26+K26+I26+G26 -> 1 | AA26: 0 | AC26: 0 | AE26: 0 | AG26: =D26-U26-W26-Y26-AA26-AC26-AE26 -> 1821 | AH26: 1821.21 | AI26: =D26-U26-W26-Y26-AA26-AC26-AE26-AG26 -> 0 | AK26: =D26-U26-W26-Y26-AA26-AC26-AE26-AG26-AI26 -> 0 | AM26: =D26-U26-W26-Y26-AA26-AC26-AE26-AG26-AI26-AK26 -> 0 | AO26: =D26-U26-W26-Y26-AA26-AC26-AE26-AG26-AI26-AK26-AM26 -> 0 | AQ26: =D26-U26-W26-Y26-AA26-AC26-AE26-AG26-AI26-AK26-AM26-AO26 -> 0 | AS26: =D26-U26-W26-Y26-AA26-AC26-AE26-AG26-AI26-AK26-AM26-AO26-AQ26 -> 0
A27: DUCHENNE | C27: 21204 | D27: 21204 | E27: 4550.16 | F27: =1311.23+350 -> 1661.23 | G27: =F27/E27 -> 0.36509266 | H27: 546.73 | I27: =H27/E27 -> 0.12015621 | J27: 1080.47 | K27: =J27/E27 -> 0.23745758 | L27: 1261.73 | M27: =L27/E27 -> 0.27729355 | O27: =N27/E27 -> 0 | Q27: =P27/E27 -> 0 | S27: =R27/E27 -> 0 | T27: =S27+Q27+O27+M27+K27+I27+G27 -> 1 | AA27: 0 | AC27: 0 | AE27: 0 | AG27: 0 | AK27: 0 | AM27: 0 | AO27: 0 | AQ27: 4550 | AR27: 4550.16 | AS27: =D27-U27-W27-Y27-AA27-AC27-AE27-AG27-AI27-AK27-AM27-AO27-AQ27 -> 16654
A28: RAOULT | C28: 6537 | D28: 6537 | E28: 6537 | G28: =F28/E28 -> 0 | I28: =H28/E28 -> 0 | K28: =J28/E28 -> 0 | L28: 6537 | M28: =L28/E28 -> 1 | O28: =N28/E28 -> 0 | Q28: =P28/E28 -> 0 | S28: =R28/E28 -> 0 | T28: =S28+Q28+O28+M28+K28+I28+G28 -> 1 | AA28: 0 | AC28: 0 | AE28: 0 | AG28: 2200 | AH28: 2200 | AI28: 2200 | AJ28: 2200 | AK28: =D28-U28-W28-Y28-AA28-AC28-AE28-AG28-AI28 -> 2137 | AL28: 2137 | AM28: =D28-U28-W28-Y28-AA28-AC28-AE28-AG28-AI28-AK28 -> 0 | AO28: =D28-U28-W28-Y28-AA28-AC28-AE28-AG28-AI28-AK28-AM28 -> 0 | AQ28: =D28-U28-W28-Y28-AA28-AC28-AE28-AG28-AI28-AK28-AM28-AO28 -> 0 | AS28: =D28-U28-W28-Y28-AA28-AC28-AE28-AG28-AI28-AK28-AM28-AO28-AQ28 -> 0
A29: VIVIER | C29: 9276 | D29: 9276 | G29: =F29/E29 -> #DIV/0! | I29: =H29/E29 -> #DIV/0! | K29: =J29/E29 -> #DIV/0! | M29: =L29/E29 -> #DIV/0! | O29: =N29/E29 -> #DIV/0! | Q29: =P29/E29 -> #DIV/0! | S29: =R29/E29 -> #DIV/0! | T29: =S29+Q29+O29+M29+K29+I29+G29 -> #DIV/0! | AA29: 0 | AC29: 0 | AE29: 0 | AG29: 0 | AI29: 0 | AK29: 0 | AM29: 0 | AO29: 0 | AS29: =D29-U29-W29-Y29-AA29-AC29-AE29-AG29-AI29-AK29-AM29-AO29-AQ29 -> 9276
A30: FOUQUES mam bassene | C30: 4328 | D30: 4328 | E30: 4328 | G30: =F30/E30 -> 0 | I30: =H30/E30 -> 0 | K30: =J30/E30 -> 0 | M30: =L30/E30 -> 0 | N30: 4328 | O30: =N30/E30 -> 1 | Q30: =P30/E30 -> 0 | S30: =R30/E30 -> 0 | T30: =S30+Q30+O30+M30+K30+I30+G30 -> 1 | AA30: 0 | AC30: 0 | AE30: 0 | AG30: 0 | AI30: 0 | AK30: 0 | AM30: 0 | AO30: =D30-U30-W30-Y30-AA30-AC30-AE30-AG30-AI30-AK30-AM30 -> 4328 | AP30: 4328 | AQ30: =D30-U30-W30-Y30-AA30-AC30-AE30-AG30-AI30-AK30-AM30-AO30 -> 0 | AS30: =D30-U30-W30-Y30-AA30-AC30-AE30-AG30-AI30-AK30-AM30-AO30-AQ30 -> 0
A31: ARCHE DES BEBES | C31: 220000 | D31: 220000 | G31: =F31/E31 -> #DIV/0! | I31: =H31/E31 -> #DIV/0! | K31: =J31/E31 -> #DIV/0! | M31: =L31/E31 -> #DIV/0! | O31: =N31/E31 -> #DIV/0! | Q31: =P31/E31 -> #DIV/0! | S31: =R31/E31 -> #DIV/0! | T31: =S31+Q31+O31+M31+K31+I31+G31 -> #DIV/0! | AA31: 0 | AC31: 0 | AE31: 0 | AG31: 0 | AI31: 0 | AK31: 0 | AQ31: 0 | AS31: =D31-U31-W31-Y31-AA31-AC31-AE31-AG31-AI31-AK31-AM31-AO31-AQ31 -> 220000
A32: CHATELIN | C32: 31053 | D32: 31053 | E32: 7316.17 | F32: 1953.41 | G32: =F32/E32 -> 0.26699899 | H32: 1837.35 | I32: =H32/E32 -> 0.2511355 | J32: 1413.6 | K32: =J32/E32 -> 0.19321585 | L32: 1860.32 | M32: =L32/E32 -> 0.25427512 | N32: 251.49 | O32: =N32/E32 -> 0.034374543 | Q32: =P32/E32 -> 0 | S32: =R32/E32 -> 0 | T32: =S32+Q32+O32+M32+K32+I32+G32 -> 1 | AA32: 0 | AC32: 0 | AE32: 0 | AG32: 0 | AI32: 0 | AK32: 0 | AM32: 0 | AO32: 0 | AQ32: 7316 | AR32: 7316.17 | AS32: =D32-U32-W32-Y32-AA32-AC32-AE32-AG32-AI32-AK32-AM32-AO32-AQ32 -> 23737
A33: MONTFOURNY | C33: 113900 | D33: 113900 | G33: =F33/E33 -> #DIV/0! | I33: =H33/E33 -> #DIV/0! | K33: =J33/E33 -> #DIV/0! | M33: =L33/E33 -> #DIV/0! | O33: =N33/E33 -> #DIV/0! | Q33: =P33/E33 -> #DIV/0! | S33: =R33/E33 -> #DIV/0! | T33: =S33+Q33+O33+M33+K33+I33+G33 -> #DIV/0! | AA33: 0 | AC33: 0 | AE33: 0 | AG33: 0 | AI33: 0 | AK33: 0 | AM33: 0 | AO33: 0 | AQ33: 0 | AS33: =D33-U33-W33-Y33-AA33-AC33-AE33-AG33-AI33-AK33-AM33-AO33-AQ33 -> 113900
A34: BRETAGNE | C34: =1278+23805.27+513.94 -> 25597.21 | D34: 25597 | E34: 25083 | F34: 5735 | G34: =F34/E34 -> 0.22864091 | H34: 2756 | I34: =H34/E34 -> 0.10987521 | J34: 3968 | K34: =J34/E34 -> 0.15819479 | M34: =L34/E34 -> 0 | N34: 5536 | O34: =N34/E34 -> 0.22070725 | P34: 2972 | Q34: =P34/E34 -> 0.11848662 | S34: =R34/E34 -> 0 | T34: =S34+Q34+O34+M34+K34+I34+G34 -> 0.8359048 | AA34: 0 | AC34: 0 | AE34: 0 | AG34: 4638.88 | AH34: 4638.88 | AI34: 12125.54 | AJ34: 12125.54 | AK34: =513.94+6693.13 -> 7207.07 | AL34: 7207 | AM34: 0 | AO34: 0 | AQ34: =D34-U34-W34-Y34-AA34-AC34-AE34-AG34-AI34-AK34-AM34-AO34 -> 1625.51 | AR34: =347.72+1278.22 -> 1625.94 | AS34: =D34-U34-W34-Y34-AA34-AC34-AE34-AG34-AI34-AK34-AM34-AO34-AQ34 -> 0
A35: GERBAULT - IBANESCU | C35: 103994 | D35: 103994 | E35: 54793.82 | F35: =28672.11+900 -> 29572.11 | G35: =F35/E35 -> 0.53969791 | H35: 8865.66 | I35: =H35/E35 -> 0.16180036 | J35: 6042.28 | K35: =J35/E35 -> 0.11027302 | L35: 5353.73 | M35: =L35/E35 -> 0.097706822 | N35: 4960.04 | O35: =N35/E35 -> 0.090521887 | Q35: =P35/E35 -> 0 | S35: =R35/E35 -> 0 | T35: =S35+Q35+O35+M35+K35+I35+G35 -> 1 | AA35: 0 | AC35: 0 | AE35: 0 | AG35: 0 | AI35: 0 | AK35: 0 | AM35: 17873 | AN35: 17872.65 | AO35: 20956 | AP35: 20956.29 | AQ35: 15965 | AR35: 15964.88 | AS35: =D35-U35-W35-Y35-AA35-AC35-AE35-AG35-AI35-AK35-AM35-AO35-AQ35 -> 49200
A36: flipo portail | C36: 1156 | D36: 1156 | E36: =D36 -> 1156 | G36: =F36/E36 -> 0 | I36: =H36/E36 -> 0 | K36: =J36/E36 -> 0 | M36: =L36/E36 -> 0 | O36: =N36/E36 -> 0 | Q36: =P36/E36 -> 0 | R36: 1156 | S36: =R36/E36 -> 1 | T36: =S36+Q36+O36+M36+K36+I36+G36 -> 1 | AA36: 0 | AC36: 0 | AE36: 0 | AG36: 0 | AK36: 1156 | AL36: 1156 | AM36: 0 | AQ36: =D36-U36-W36-Y36-AA36-AC36-AE36-AG36-AI36-AK36-AM36-AO36 -> 0 | AS36: =D36-U36-W36-Y36-AA36-AC36-AE36-AG36-AI36-AK36-AM36-AO36-AQ36 -> 0
A37: LECLEIR | C37: 29905.67 | D37: 29905.67 | E37: 23943.63 | F37: =900+4166.86 -> 5066.86 | G37: =F37/E37 -> 0.2116162 | H37: 4047.32 | I37: =H37/E37 -> 0.16903536 | J37: 6779.41 | K37: =J37/E37 -> 0.28314044 | L37: 6401.03 | M37: =L37/E37 -> 0.26733749 | N37: 1649.01 | O37: =N37/E37 -> 0.06887051 | P37: 0 | Q37: =P37/E37 -> 0 | S37: =R37/E37 -> 0 | T37: =S37+Q37+O37+M37+K37+I37+G37 -> 1 | AA37: 0 | AC37: 0 | AE37: 0 | AG37: 0 | AI37: 0 | AK37: 9114 | AL37: 9114 | AM37: 0 | AO37: 0 | AQ37: 14829 | AR37: 14829.45 | AS37: =D37-U37-W37-Y37-AA37-AC37-AE37-AG37-AI37-AK37-AM37-AO37-AQ37 -> 5962.67
A38: PORET | C38: =102969+4565.34 -> 107534.34 | D38: =C38 -> 107534.34 | E38: =D38 -> 107534.34 | F38: =900+30470.52 -> 31370.52 | G38: =F38/E38 -> 0.2917256 | H38: 7411.6 | I38: =H38/E38 -> 0.068923099 | J38: 26534.23 | K38: =J38/E38 -> 0.24675122 | L38: 32026.98 | M38: =L38/E38 -> 0.29783026 | N38: 5626.38 | O38: =N38/E38 -> 0.052321705 | Q38: =P38/E38 -> 0 | S38: =R38/E38 -> 0 | T38: =S38+Q38+O38+M38+K38+I38+G38 -> 0.95755189 | AA38: 0 | AC38: 0 | AE38: 0 | AG38: 0 | AI38: 24126.36 | AJ38: 24126.36 | AK38: 0 | AM38: 45000 | AN38: 44999.97 | AO38: 0 | AQ38: =D38-U38-W38-Y38-AA38-AC38-AE38-AG38-AI38-AK38-AM38-AO38 -> 38407.98 | AR38: =33843.38+4565.34 -> 38408.72 | AS38: =D38-U38-W38-Y38-AA38-AC38-AE38-AG38-AI38-AK38-AM38-AO38-AQ38 -> 0
A39: CLET CARON | C39: 176738.45 | D39: 176738 | E39: 155790.78 | F39: =1125+37272.35+3789.69 -> 42187.04 | G39: =F39/E39 -> 0.27079292 | H39: =15386.94+3582.6 -> 18969.54 | I39: =H39/E39 -> 0.12176292 | J39: =23156.77+868 -> 24024.77 | K39: =J39/E39 -> 0.15421176 | L39: =28481.54+3341.42 -> 31822.96 | M39: =L39/E39 -> 0.20426729 | N39: 11789.22 | O39: =N39/E39 -> 0.075673413 | P39: =25531.58+1465.67 -> 26997.25 | Q39: =P39/E39 -> 0.17329171 | S39: =R39/E39 -> 0 | T39: =S39+Q39+O39+M39+K39+I39+G39 -> 1 | AA39: 0 | AC39: 0 | AE39: 0 | AG39: 15114 | AH39: 15113.6 | AI39: 20142.54 | AJ39: 20142.54 | AK39: 45108.16 | AL39: 45108.16 | AM39: 25071 | AN39: 25071.24 | AO39: 37411 | AP39: 37411.21 | AQ39: 12944 | AR39: 12944 | AS39: =D39-U39-W39-Y39-AA39-AC39-AE39-AG39-AI39-AK39-AM39-AO39-AQ39 -> 20947.3
A40: BICART | C40: 7093 | D40: 7093 | E40: 7093 | G40: =F40/E40 -> 0 | I40: =H40/E40 -> 0 | K40: =J40/E40 -> 0 | M40: =L40/E40 -> 0 | O40: =N40/E40 -> 0 | Q40: =P40/E40 -> 0 | R40: 7093 | S40: =R40/E40 -> 1 | T40: =S40+Q40+O40+M40+K40+I40+G40 -> 1 | AA40: 0 | AC40: 0 | AE40: 0 | AG40: 7093 | AH40: 7092.9 | AI40: =D40-U40-W40-Y40-AA40-AC40-AE40-AG40 -> 0 | AK40: =D40-U40-W40-Y40-AA40-AC40-AE40-AG40-AI40 -> 0 | AM40: =D40-U40-W40-Y40-AA40-AC40-AE40-AG40-AI40-AK40 -> 0 | AO40: =D40-U40-W40-Y40-AA40-AC40-AE40-AG40-AI40-AK40-AM40 -> 0 | AQ40: =D40-U40-W40-Y40-AA40-AC40-AE40-AG40-AI40-AK40-AM40-AO40 -> 0 | AS40: =D40-U40-W40-Y40-AA40-AC40-AE40-AG40-AI40-AK40-AM40-AO40-AQ40 -> 0
A41: MAIRIE EVRECY | C41: 8521 | D41: 8521 | E41: =D41 -> 8521 | G41: =F41/E41 -> 0 | I41: =H41/E41 -> 0 | K41: =J41/E41 -> 0 | L41: 8521 | M41: =L41/E41 -> 1 | O41: =N41/E41 -> 0 | Q41: =P41/E41 -> 0 | S41: =R41/E41 -> 0 | T41: =S41+Q41+O41+M41+K41+I41+G41 -> 1 | AA41: 0 | AC41: 0 | AE41: 0 | AG41: =D41-U41-W41-Y41-AA41-AC41-AE41 -> 8521 | AH41: 8521.3 | AI41: =D41-U41-W41-Y41-AA41-AC41-AE41-AG41 -> 0 | AK41: =D41-U41-W41-Y41-AA41-AC41-AE41-AG41-AI41 -> 0 | AM41: =D41-U41-W41-Y41-AA41-AC41-AE41-AG41-AI41-AK41 -> 0 | AO41: =D41-U41-W41-Y41-AA41-AC41-AE41-AG41-AI41-AK41-AM41 -> 0 | AQ41: =D41-U41-W41-Y41-AA41-AC41-AE41-AG41-AI41-AK41-AM41-AO41 -> 0 | AS41: =D41-U41-W41-Y41-AA41-AC41-AE41-AG41-AI41-AK41-AM41-AO41-AQ41 -> 0
A42: HUARD | C42: 36011 | D42: 36011 | G42: =F42/E42 -> #DIV/0! | I42: =H42/E42 -> #DIV/0! | K42: =J42/E42 -> #DIV/0! | M42: =L42/E42 -> #DIV/0! | O42: =N42/E42 -> #DIV/0! | Q42: =P42/E42 -> #DIV/0! | S42: =R42/E42 -> #DIV/0! | T42: =S42+Q42+O42+M42+K42+I42+G42 -> #DIV/0! | AA42: 0 | AC42: 0 | AE42: 0 | AG42: 0 | AI42: 0 | AK42: 0 | AM42: 0 | AO42: 0 | AQ42: 5122 | AR42: 5121.79 | AS42: =D42-U42-W42-Y42-AA42-AC42-AE42-AG42-AI42-AK42-AM42-AO42-AQ42 -> 30889
A43: GUEDON | C43: 124336 | D43: 124336 | E43: 76047.9 | F43: =21526.05+900 -> 22426.05 | G43: =F43/E43 -> 0.29489374 | H43: 13992 | I43: =H43/E43 -> 0.1839893 | J43: 20605 | K43: =J43/E43 -> 0.27094765 | L43: 10804.32 | M43: =L43/E43 -> 0.14207256 | N43: 3606.93 | O43: =N43/E43 -> 0.047429712 | P43: 4612.89 | Q43: =P43/E43 -> 0.060657691 | R43: 0 | S43: =R43/E43 -> 0 | T43: =S43+Q43+O43+M43+K43+I43+G43 -> 0.99999066 | AA43: 0 | AC43: 0 | AE43: 0 | AG43: 15130.7 | AH43: 15130.7 | AI43: 0 | AK43: 26642.61 | AL43: 26642.61 | AM43: 10462 | AN43: 10462.29 | AO43: 0 | AQ43: 23812 | AR43: 23812.3 | AS43: =D43-U43-W43-Y43-AA43-AC43-AE43-AG43-AI43-AK43-AM43-AO43-AQ43 -> 48288.69
A44: FROGER | C44: ='2019-20'!AC17 -> 1913.88 | D44: =C44 -> 1913.88 | G44: =F44/E44 -> #DIV/0! | I44: =H44/E44 -> #DIV/0! | K44: =J44/E44 -> #DIV/0! | M44: =L44/E44 -> #DIV/0! | O44: =N44/E44 -> #DIV/0! | Q44: =P44/E44 -> #DIV/0! | S44: =R44/E44 -> #DIV/0! | T44: =S44+Q44+O44+M44+K44+I44+G44 -> #DIV/0! | AA44: 0 | AC44: 0 | AE44: 0 | AG44: 0 | AI44: 0 | AK44: 0 | AM44: 0 | AO44: 0 | AQ44: 0 | AS44: =D44-U44-W44-Y44-AA44-AC44-AE44-AG44-AI44-AK44-AM44-AO44-AQ44 -> 1913.88
...

Sheet 2021-22
D3: =D35+D36+D42+D54+D57+D58+D62+D66+D68+D69+D76 -> 400334.3
F4: OSSATURE | G4: OB | H4: CHARPENTE | I4: CB | J4: MENUISERIE | K4: MX | L4: BARDAGE | M4: BA | N4: ISOLATION | O4: IEA | P4: PLATRERIE | Q4: PII | R4: DIVERS | S4: DIV | T4: ETUDE SUIVI | U4: DIV | W4: OCTOBRE | Y4: NOVEMBRE | AA4: DECEMBRE | AC4: JANVIER | AE4: FEVRIER | AG4: MARS | AI4: AVRIL | AK4: MAI | AM4: JUIN | AO4: JUILLET | AQ4: AOUT | AS4: SEPTEMBRE
A5: NOM | C5: CA/prevision | D5: CA/contrat | F5: BOIS | G5: % | H5: BOIS | I5: % | J5: EXTERIEURE | K5: % | L5: EXT | M5: % | N5: ETANCHEITE | O5: % | P5: ISO INT MI | Q5: % | S5: % | U5: % | W5: prévu | X5: réalisé | Y5: prévu | Z5: réalisé | AA5: prévu | AB5: réalisé | AC5: prévu | AD5: réalisé | AE5: prévu | AF5: réalisé | AG5: prévu | AH5: réalisé | AI5: prévu | AJ5: réalisé | AK5: prévu | AL5: réalisé | AM5: prévu | AN5: réalisé | AO5: prévu | AP5: réalisé | AQ5: prévu | AR5: réalisé | AS5: prévu | AT5: réalisé | AU5: 2022/2023
A7: Commission PASQUET
A8: Commission PASQUET
A9: Commission PASQUET
A10: Commission PASQUET
A11: Commission ST
A12: loret avoir
D14: =C14 -> 0 | G14: =F14/E14 -> #DIV/0! | I14: =H14/E14 -> #DIV/0! | K14: =J14/E14 -> #DIV/0! | M14: =L14/E14 -> #DIV/0! | O14: =N14/E14 -> #DIV/0! | Q14: =P14/E14 -> #DIV/0! | S14: =R14/E14 -> #DIV/0! | U14: =T14/E14 -> #DIV/0! | V14: =U14+S14+Q14+O14+M14+K14+I14+G14 -> #DIV/0! | W14: 0 | Y14: =D14-W14 -> 0 | AA14: =D14-W14-Y14 -> 0 | AC14: =D14-W14-Y14-AA14 -> 0 | AE14: =D14-W14-Y14-AA14-AC14 -> 0 | AG14: =D14-W14-Y14-AA14-AC14-AE14 -> 0 | AI14: =D14-W14-Y14-AA14-AC14-AE14-AG14 -> 0 | AK14: =D14-W14-Y14-AA14-AC14-AE14-AG14-AI14 -> 0 | AM14: =D14-W14-Y14-AA14-AC14-AE14-AG14-AI14-AK14 -> 0 | AO14: =D14-W14-Y14-AA14-AC14-AE14-AG14-AI14-AK14-AM14 -> 0 | AQ14: =D14-W14-Y14-AA14-AC14-AE14-AG14-AI14-AK14-AM14-AO14 -> 0 | AS14: =D14-W14-Y14-AA14-AC14-AE14-AG14-AI14-AK14-AM14-AO14-AQ14 -> 0 | AU14: =D14-W14-Y14-AA14-AC14-AE14-AG14-AI14-AK14-AM14-AO14-AQ14-AS14 -> 0
D15: =C15 -> 0 | G15: =F15/E15 -> #DIV/0! | I15: =H15/E15 -> #DIV/0! | K15: =J15/E15 -> #DIV/0! | M15: =L15/E15 -> #DIV/0! | O15: =N15/E15 -> #DIV/0! | Q15: =P15/E15 -> #DIV/0! | S15: =R15/E15 -> #DIV/0! | U15: =T15/E15 -> #DIV/0! | V15: =U15+S15+Q15+O15+M15+K15+I15+G15 -> #DIV/0! | W15: 0 | Y15: =D15-W15 -> 0 | AA15: =D15-W15-Y15 -> 0 | AC15: =D15-W15-Y15-AA15 -> 0 | AE15: =D15-W15-Y15-AA15-AC15 -> 0 | AG15: =D15-W15-Y15-AA15-AC15-AE15 -> 0 | AI15: =D15-W15-Y15-AA15-AC15-AE15-AG15 -> 0 | AK15: =D15-W15-Y15-AA15-AC15-AE15-AG15-AI15 -> 0 | AM15: =D15-W15-Y15-AA15-AC15-AE15-AG15-AI15-AK15 -> 0 | AO15: =D15-W15-Y15-AA15-AC15-AE15-AG15-AI15-AK15-AM15 -> 0 | AQ15: =D15-W15-Y15-AA15-AC15-AE15-AG15-AI15-AK15-AM15-AO15 -> 0 | AS15: =D15-W15-Y15-AA15-AC15-AE15-AG15-AI15-AK15-AM15-AO15-AQ15 -> 0 | AU15: =D15-W15-Y15-AA15-AC15-AE15-AG15-AI15-AK15-AM15-AO15-AQ15-AS15 -> 0
D16: =C16 -> 0 | G16: =F16/E16 -> #DIV/0! | I16: =H16/E16 -> #DIV/0! | K16: =J16/E16 -> #DIV/0! | M16: =L16/E16 -> #DIV/0! | O16: =N16/E16 -> #DIV/0! | Q16: =P16/E16 -> #DIV/0! | S16: =R16/E16 -> #DIV/0! | U16: =T16/E16 -> #DIV/0! | V16: =U16+S16+Q16+O16+M16+K16+I16+G16 -> #DIV/0! | W16: 0 | Y16: 0 | AA16: =D16-W16-Y16 -> 0 | AC16: =D16-W16-Y16-AA16 -> 0 | AE16: =D16-W16-Y16-AA16-AC16 -> 0 | AG16: =D16-W16-Y16-AA16-AC16-AE16 -> 0 | AI16: =D16-W16-Y16-AA16-AC16-AE16-AG16 -> 0 | AK16: =D16-W16-Y16-AA16-AC16-AE16-AG16-AI16 -> 0 | AM16: =D16-W16-Y16-AA16-AC16-AE16-AG16-AI16-AK16 -> 0 | AO16: =D16-W16-Y16-AA16-AC16-AE16-AG16-AI16-AK16-AM16 -> 0 | AQ16: =D16-W16-Y16-AA16-AC16-AE16-AG16-AI16-AK16-AM16-AO16 -> 0 | AS16: =D16-W16-Y16-AA16-AC16-AE16-AG16-AI16-AK16-AM16-AO16-AQ16 -> 0 | AU16: =D16-W16-Y16-AA16-AC16-AE16-AG16-AI16-AK16-AM16-AO16-AQ16-AS16 -> 0
D17: =C17 -> 0 | G17: =F17/E17 -> #DIV/0! | I17: =H17/E17 -> #DIV/0! | K17: =J17/E17 -> #DIV/0! | M17: =L17/E17 -> #DIV/0! | O17: =N17/E17 -> #DIV/0! | Q17: =P17/E17 -> #DIV/0! | S17: =R17/E17 -> #DIV/0! | U17: =T17/E17 -> #DIV/0! | V17: =U17+S17+Q17+O17+M17+K17+I17+G17 -> #DIV/0! | W17: 0 | Y17: =D17-W17 -> 0 | AA17: =D17-W17-Y17 -> 0 | AC17: =D17-W17-Y17-AA17 -> 0 | AE17: =D17-W17-Y17-AA17-AC17 -> 0 | AG17: =D17-W17-Y17-AA17-AC17-AE17 -> 0 | AI17: =D17-W17-Y17-AA17-AC17-AE17-AG17 -> 0 | AK17: =D17-W17-Y17-AA17-AC17-AE17-AG17-AI17 -> 0 | AM17: =D17-W17-Y17-AA17-AC17-AE17-AG17-AI17-AK17 -> 0 | AO17: =D17-W17-Y17-AA17-AC17-AE17-AG17-AI17-AK17-AM17 -> 0 | AQ17: =D17-W17-Y17-AA17-AC17-AE17-AG17-AI17-AK17-AM17-AO17 -> 0 | AS17: =D17-W17-Y17-AA17-AC17-AE17-AG17-AI17-AK17-AM17-AO17-AQ17 -> 0 | AU17: =D17-W17-Y17-AA17-AC17-AE17-AG17-AI17-AK17-AM17-AO17-AQ17-AS17 -> 0
D18: =C18 -> 0 | G18: =F18/E18 -> #DIV/0! | I18: =H18/E18 -> #DIV/0! | K18: =J18/E18 -> #DIV/0! | M18: =L18/E18 -> #DIV/0! | O18: =N18/E18 -> #DIV/0! | Q18: =P18/E18 -> #DIV/0! | S18: =R18/E18 -> #DIV/0! | U18: =T18/E18 -> #DIV/0! | V18: =U18+S18+Q18+O18+M18+K18+I18+G18 -> #DIV/0! | W18: 0 | Y18: =D18-W18 -> 0 | AA18: =D18-W18-Y18 -> 0 | AC18: =D18-W18-Y18-AA18 -> 0 | AE18: =D18-W18-Y18-AA18-AC18 -> 0 | AG18: =D18-W18-Y18-AA18-AC18-AE18 -> 0 | AI18: =D18-W18-Y18-AA18-AC18-AE18-AG18 -> 0 | AK18: =D18-W18-Y18-AA18-AC18-AE18-AG18-AI18 -> 0 | AM18: =D18-W18-Y18-AA18-AC18-AE18-AG18-AI18-AK18 -> 0 | AO18: =D18-W18-Y18-AA18-AC18-AE18-AG18-AI18-AK18-AM18 -> 0 | AQ18: =D18-W18-Y18-AA18-AC18-AE18-AG18-AI18-AK18-AM18-AO18 -> 0 | AS18: =D18-W18-Y18-AA18-AC18-AE18-AG18-AI18-AK18-AM18-AO18-AQ18 -> 0 | AU18: =D18-W18-Y18-AA18-AC18-AE18-AG18-AI18-AK18-AM18-AO18-AQ18-AS18 -> 0
D19: =C19 -> 0 | G19: =F19/E19 -> #DIV/0! | I19: =H19/E19 -> #DIV/0! | K19: =J19/E19 -> #DIV/0! | M19: =L19/E19 -> #DIV/0! | O19: =N19/E19 -> #DIV/0! | Q19: =P19/E19 -> #DIV/0! | S19: =R19/E19 -> #DIV/0! | U19: =T19/E19 -> #DIV/0! | V19: =U19+S19+Q19+O19+M19+K19+I19+G19 -> #DIV/0! | W19: 0 | Y19: 0 | AA19: =D19-W19-Y19 -> 0 | AC19: =D19-W19-Y19-AA19 -> 0 | AE19: =D19-W19-Y19-AA19-AC19 -> 0 | AG19: =D19-W19-Y19-AA19-AC19-AE19 -> 0 | AI19: =D19-W19-Y19-AA19-AC19-AE19-AG19 -> 0 | AK19: =D19-W19-Y19-AA19-AC19-AE19-AG19-AI19 -> 0 | AM19: =D19-W19-Y19-AA19-AC19-AE19-AG19-AI19-AK19 -> 0 | AO19: =D19-W19-Y19-AA19-AC19-AE19-AG19-AI19-AK19-AM19 -> 0 | AQ19: =D19-W19-Y19-AA19-AC19-AE19-AG19-AI19-AK19-AM19-AO19 -> 0 | AS19: =D19-W19-Y19-AA19-AC19-AE19-AG19-AI19-AK19-AM19-AO19-AQ19 -> 0 | AU19: =D19-W19-Y19-AA19-AC19-AE19-AG19-AI19-AK19-AM19-AO19-AQ19-AS19 -> 0
A20: CHATELET | C20: 864 | D20: =C20 -> 864 | E20: =D20 -> 864 | G20: =F20/E20 -> 0 | I20: =H20/E20 -> 0 | K20: =J20/E20 -> 0 | M20: =L20/E20 -> 0 | O20: =N20/E20 -> 0 | Q20: =P20/E20 -> 0 | S20: =R20/E20 -> 0 | T20: 864 | U20: =T20/E20 -> 1 | V20: =U20+S20+Q20+O20+M20+K20+I20+G20 -> 1 | W20: 0 | Y20: 0 | AA20: 0 | AC20: 0 | AE20: 0 | AG20: 0 | AI20: 0 | AK20: 0 | AM20: 0 | AO20: 0 | AQ20: 0 | AS20: =D20-W20-Y20-AA20-AC20-AE20-AG20-AI20-AK20-AM20-AO20-AQ20 -> 864 | AT20: 864 | AU20: =D20-W20-Y20-AA20-AC20-AE20-AG20-AI20-AK20-AM20-AO20-AQ20-AS20 -> 0
A21: bernard | C21: =24478+1339.94 -> 25817.94 | D21: =23536+942+1339.94 -> 25817.94 | E21: 24478 | G21: =F21/E21 -> 0 | I21: =H21/E21 -> 0 | J21: 24478 | K21: =J21/E21 -> 1 | M21: =L21/E21 -> 0 | O21: =N21/E21 -> 0 | Q21: =P21/E21 -> 0 | S21: =R21/E21 -> 0 | U21: =T21/E21 -> 0 | V21: =U21+S21+Q21+O21+M21+K21+I21+G21 -> 1 | W21: 0 | Y21: 0 | AA21: 0 | AC21: 0 | AE21: 0 | AG21: 0 | AI21: 0 | AK21: 0 | AM21: 0 | AO21: 0 | AQ21: 24478 | AR21: 24478 | AS21: =D21-W21-Y21-AA21-AC21-AE21-AG21-AI21-AK21-AM21-AO21-AQ21 -> 1339.94 | AT21: 1339.94 | AU21: =D21-W21-Y21-AA21-AC21-AE21-AG21-AI21-AK21-AM21-AO21-AQ21-AS21 -> 0
A22: LEMOINE | C22: 51440.55 | D22: =C22 -> 51440.55 | G22: =F22/E22 -> #DIV/0! | I22: =H22/E22 -> #DIV/0! | K22: =J22/E22 -> #DIV/0! | M22: =L22/E22 -> #DIV/0! | O22: =N22/E22 -> #DIV/0! | Q22: =P22/E22 -> #DIV/0! | S22: =R22/E22 -> #DIV/0! | U22: =T22/E22 -> #DIV/0! | V22: =U22+S22+Q22+O22+M22+K22+I22+G22 -> #DIV/0! | W22: 0 | Y22: 0 | AA22: 0 | AC22: 0 | AE22: 0 | AG22: 0 | AI22: 0 | AK22: 0 | AM22: 0 | AO22: 0 | AQ22: 0 | AS22: 0 | AU22: =D22-W22-Y22-AA22-AC22-AE22-AG22-AI22-AK22-AM22-AO22-AQ22-AS22 -> 51440.55
A23: CHATRE | C23: 20149.4 | D23: =C23 -> 20149.4 | G23: =F23/E23 -> #DIV/0! | I23: =H23/E23 -> #DIV/0! | K23: =J23/E23 -> #DIV/0! | M23: =L23/E23 -> #DIV/0! | O23: =N23/E23 -> #DIV/0! | Q23: =P23/E23 -> #DIV/0! | S23: =R23/E23 -> #DIV/0! | U23: =T23/E23 -> #DIV/0! | V23: =U23+S23+Q23+O23+M23+K23+I23+G23 -> #DIV/0! | W23: 0 | Y23: 0 | AA23: 0 | AC23: 0 | AE23: 0 | AG23: 0 | AI23: 0 | AK23: 0 | AM23: 0 | AO23: 0 | AQ23: 0 | AS23: 0 | AU23: =D23-W23-Y23-AA23-AC23-AE23-AG23-AI23-AK23-AM23-AO23-AQ23-AS23 -> 20149.4
A24: BASSIERE 2 | C24: =400+6799.86+887.11+9560.51+10014.49+2380.91 -> 30042.88 | D24: =C24 -> 30042.88 | G24: =F24/E24 -> #DIV/0! | I24: =H24/E24 -> #DIV/0! | K24: =J24/E24 -> #DIV/0! | M24: =L24/E24 -> #DIV/0! | O24: =N24/E24 -> #DIV/0! | Q24: =P24/E24 -> #DIV/0! | S24: =R24/E24 -> #DIV/0! | U24: =T24/E24 -> #DIV/0! | V24: =U24+S24+Q24+O24+M24+K24+I24+G24 -> #DIV/0! | W24: 0 | Y24: 0 | AA24: 0 | AC24: 0 | AE24: 0 | AG24: 0 | AI24: 0 | AK24: 0 | AM24: 0 | AO24: 0 | AQ24: 0 | AS24: 0 | AU24: =D24-W24-Y24-AA24-AC24-AE24-AG24-AI24-AK24-AM24-AO24-AQ24-AS24 -> 30042.88
A25: LEPLE | C25: 98094.97 | D25: =C25 -> 98094.97 | G25: =F25/E25 -> #DIV/0! | I25: =H25/E25 -> #DIV/0! | K25: =J25/E25 -> #DIV/0! | M25: =L25/E25 -> #DIV/0! | O25: =N25/E25 -> #DIV/0! | Q25: =P25/E25 -> #DIV/0! | S25: =R25/E25 -> #DIV/0! | U25: =T25/E25 -> #DIV/0! | V25: =U25+S25+Q25+O25+M25+K25+I25+G25 -> #DIV/0! | W25: 0 | Y25: 0 | AA25: 0 | AC25: 0 | AE25: 0 | AG25: 0 | AI25: 0 | AK25: 0 | AM25: 0 | AO25: 0 | AQ25: 0 | AS25: 0 | AU25: =D25-W25-Y25-AA25-AC25-AE25-AG25-AI25-AK25-AM25-AO25-AQ25-AS25 -> 98094.97
A26: HOFLACK | C26: =7808.84+12085.6 -> 19894.44 | D26: =C26 -> 19894.44 | E26: =D26 -> 19894.44 | G26: =F26/E26 -> 0 | H26: =E26-480-576 -> 18838.44 | I26: =H26/E26 -> 0.94691984 | K26: =J26/E26 -> 0 | M26: =L26/E26 -> 0 | O26: =N26/E26 -> 0 | Q26: =P26/E26 -> 0 | S26: =R26/E26 -> 0 | T26: =E26-H26 -> 1056 | U26: =T26/E26 -> 0.053080157 | V26: =U26+S26+Q26+O26+M26+K26+I26+G26 -> 1 | W26: 0 | Y26: 0 | AA26: 0 | AC26: 0 | AE26: 0 | AG26: 0 | AI26: 0 | AK26: 0 | AM26: 0 | AO26: 0 | AQ26: 0 | AS26: 4384 | AT26: =1834.82+2549.19 -> 4384.01 | AU26: =D26-W26-Y26-AA26-AC26-AE26-AG26-AI26-AK26-AM26-AO26-AQ26-AS26 -> 15510.44
A27: KGBR | C27: =20418.25+366.7-141+1506 -> 22149.95 | D27: =C27 -> 22149.95 | E27: =D27 -> 22149.95 | F27: 17058 | G27: =F27/E27 -> 0.77011461 | I27: =H27/E27 -> 0 | K27: =J27/E27 -> 0 | M27: =L27/E27 -> 0 | N27: 1975 | O27: =N27/E27 -> 0.089164987 | P27: 1506 | Q27: =P27/E27 -> 0.067991124 | S27: =R27/E27 -> 0 | T27: 1614 | U27: =T27/E27 -> 0.072866982 | V27: =U27+S27+Q27+O27+M27+K27+I27+G27 -> 1.0001377 | W27: 0 | Y27: 0 | AA27: 0 | AC27: 0 | AE27: 0 | AG27: 0 | AI27: 0 | AK27: 0 | AO27: =20418.84+366.7 -> 20785.54 | AP27: 20786 | AQ27: -142 | AR27: -142 | AS27: 1506.81 | AT27: 1506.81 | AU27: =D27-W27-Y27-AA27-AC27-AE27-AG27-AI27-AK27-AM27-AO27-AQ27-AS27 -> -0.4
A28: GRARD | C28: 55005 | D28: =C28 -> 55005 | G28: =F28/E28 -> #DIV/0! | I28: =H28/E28 -> #DIV/0! | K28: =J28/E28 -> #DIV/0! | M28: =L28/E28 -> #DIV/0! | O28: =N28/E28 -> #DIV/0! | Q28: =P28/E28 -> #DIV/0! | S28: =R28/E28 -> #DIV/0! | U28: =T28/E28 -> #DIV/0! | V28: =U28+S28+Q28+O28+M28+K28+I28+G28 -> #DIV/0! | W28: 0 | Y28: 0 | AA28: 0 | AC28: 0 | AE28: 0 | AG28: 0 | AI28: 0 | AK28: 0 | AM28: 0 | AO28: 0 | AQ28: 0 | AS28: 0 | AU28: =D28-W28-Y28-AA28-AC28-AE28-AG28-AI28-AK28-AM28-AO28-AQ28-AS28 -> 55005
A29: LAINE JAMET | C29: 48991.13 | D29: =C29 -> 48991.13 | E29: 48991 | F29: 17111.92 | G29: =F29/E29 -> 0.34928701 | H29: 7777.07 | I29: =H29/E29 -> 0.15874487 | K29: =J29/E29 -> 0 | L29: 17708.7 | M29: =L29/E29 -> 0.36146843 | N29: 4953.44 | O29: =N29/E29 -> 0.10110918 | Q29: =P29/E29 -> 0 | S29: =R29/E29 -> 0 | T29: 1440 | U29: =T29/E29 -> 0.029393154 | V29: =U29+S29+Q29+O29+M29+K29+I29+G29 -> 1.0000027 | W29: 0 | Y29: 0 | AA29: 0 | AC29: 0 | AE29: 0 | AG29: 0 | AI29: 0 | AK29: 0 | AM29: 0 | AO29: 0 | AQ29: 0 | AS29: 0 | AU29: =D29-W29-Y29-AA29-AC29-AE29-AG29-AI29-AK29-AM29-AO29-AQ29-AS29 -> 48991.13
A30: mairie de perrière 2 | C30: 9393.34 | D30: =C30 -> 9393.34 | E30: 9393 | G30: =F30/E30 -> 0 | H30: 9393 | I30: =H30/E30 -> 1 | K30: =J30/E30 -> 0 | M30: =L30/E30 -> 0 | O30: =N30/E30 -> 0 | Q30: =P30/E30 -> 0 | S30: =R30/E30 -> 0 | U30: =T30/E30 -> 0 | V30: =U30+S30+Q30+O30+M30+K30+I30+G30 -> 1 | W30: 0 | Y30: 0 | AA30: 0 | AC30: 0 | AE30: 0 | AG30: 0 | AI30: 0 | AK30: 0 | AM30: 0 | AO30: 0 | AQ30: 0 | AS30: 0 | AU30: =D30-W30-Y30-AA30-AC30-AE30-AG30-AI30-AK30-AM30-AO30-AQ30-AS30 -> 9393.34
G31: =F31/E31 -> #DIV/0! | I31: =H31/E31 -> #DIV/0! | K31: =J31/E31 -> #DIV/0! | M31: =L31/E31 -> #DIV/0! | O31: =N31/E31 -> #DIV/0! | Q31: =P31/E31 -> #DIV/0! | S31: =R31/E31 -> #DIV/0! | U31: =T31/E31 -> #DIV/0! | V31: =U31+S31+Q31+O31+M31+K31+I31+G31 -> #DIV/0! | W31: 0 | Y31: 0 | AA31: 0 | AC31: 0 | AE31: 0 | AG31: 0 | AI31: 0 | AK31: 0 | AM31: 0 | AO31: =D31-W31-Y31-AA31-AC31-AE31-AG31-AI31-AK31-AM31 -> 0 | AQ31: =D31-W31-Y31-AA31-AC31-AE31-AG31-AI31-AK31-AM31-AO31 -> 0 | AS31: =D31-W31-Y31-AA31-AC31-AE31-AG31-AI31-AK31-AM31-AO31-AQ31 -> 0 | AU31: =D31-W31-Y31-AA31-AC31-AE31-AG31-AI31-AK31-AM31-AO31-AQ31-AS31 -> 0
G32: =F32/E32 -> #DIV/0! | I32: =H32/E32 -> #DIV/0! | K32: =J32/E32 -> #DIV/0! | M32: =L32/E32 -> #DIV/0! | O32: =N32/E32 -> #DIV/0! | Q32: =P32/E32 -> #DIV/0! | S32: =R32/E32 -> #DIV/0! | U32: =T32/E32 -> #DIV/0! | V32: =U32+S32+Q32+O32+M32+K32+I32+G32 -> #DIV/0! | W32: 0 | Y32: 0 | AA32: 0 | AC32: 0 | AE32: 0 | AG32: 0 | AI32: 0 | AK32: 0 | AM32: 0 | AO32: 0 | AQ32: 0 | AS32: 0 | AU32: =D32-W32-Y32-AA32-AC32-AE32-AG32-AI32-AK32-AM32-AO32-AQ32-AS32 -> 0
